Workbook
Name Fragmentator_Klient: #N/A
Name NatywnaOśCzasu_Data: #N/A

Sheet ExceliAdam
Z2: Newsletter (info o webinarach, pliki końcowe po webinarach itp.)
Z4: http://exceliadam.getleads.pl/newsletter/
R5: KURSY WIDEO | BF5: KSIĄŻKI
Z9: Mistrz Excela - wprowadzi Cię w tajniki Excela, od podstawowych zagadnień, przez tabele przestawne i wyszukiwanie pionowo | BN9: Nakład wyczerpany - książka dostępna w wersji elektornicznej
BN12: http://ksplus.komputerswiat.pl/sklep#mistrz-excela-w-20-dni
Z14: aż po wstęp do programowania VBA (rejestrowanie makr).
Z17: https://www.udemy.com/mistrz-excela/?couponCode=STANDARDOWY
Z21: Excel Mistrz Formuł - poznaj najczęściej wykorzystywane funkcje w Excelu
Z23: i stań się mistrzem formuł
Z26: https://www.udemy.com/excel-mistrz-formul/?couponCode=STANDARDOWY
Z32: Mistrz Power Query - poznaj tajniki pobierania, łączenia, przekształcania, grupowania, parametryzacji
BN34: Standardowa księgarnia
Z37: oraz tworzenia własnych funkcji w dodatku do Excela Power Query | BN37: https://literia.pl/excel-w-przykladach-zaawansowane-funkcje-krok-po-kroku
Z40: https://www.udemy.com/mistrz-power-query/?couponCode=STANDARDOWY | BN40: Książka w wersji elektronicznej:
Z43: Dashboardy w Excelu - kurs nauczy Cię prezentować dane na Panelach Menadżerskich, dzięki czemu będą bardziej czytelne | BN43: http://ksplus.komputerswiat.pl/sklep#biblioteczka-1-2016
Z48: oraz będziesz mógł wprowadzić w prezentacji dynamiczne elementy.
B51: http://www.ExceliAdam.pl | Z51: https://www.udemy.com/excel-dashboardy/?couponCode=STANDARDOWY
B54: Więcej wiedzy na YouTubie | Z54: VBA w 30 dni - kurs wprowadzi Cię w tajniki programowania w Excelu, czyli nauczy Cię jak rejestrować, pisać oraz automatycznie
B57: https://www.youtube.com/ExceliAdam
Z59: uruchamiać makra, a tym samym zautomatyzować wiele czynności w Excelu | BN59: Standardowa księgarnia
B60: Polub moją stronę na facebooku ;)
Z62: https://www.udemy.com/excel-vba-makra/?couponCode=STANDARDOWY | BN62: https://literia.pl/excel-50-najwazniejszych-funkcji
B63: https://web.facebook.com/ExceliAdam/
Z65: Power BI - nowe narzędzie Microsoftu, które pozwala Ci pobierać, analizować, a na koniec wizualizować dane | BN65: Książka w wersji elektronicznej:
BN68: http://ksplus.komputerswiat.pl/sklep#biblioteczka-2-2019
Z71: https://www.udemy.com/power-bi-microsoft/?couponCode=STANDARDOWY
Z77: W przypadku Standardowych linków promocyjnych warto sprawdzić czy Udemy nie ma aktualnie lepszej propozycji niż moja.
Z82: Czyli wejść przez podany przeze mnie link do kursu (żeby sprzadaż kursu została zaliczona dla mnie, a nie dla Udemy, wtedy mam większą prowizję, ze sprzedaży mojego kursu),
Z90: a następnie usunąć końcówkę: ?couponCode=STANDARDOWY

Sheet Podstawy
A1: Data | B1: Województwo | C1: Klient | D1: Sprzedawca | E1: Produkt | F1: Sprzedaż | H1: Suma sprzedaż
A2: 41311 | B2: Dolnośląskie | C2: US | D2: Melman | E2: Słońce | F2: 1677.5 | H2: Produkt/Sprzedawca | I2: Aleks | J2: Gloria | K2: Maurycy | L2: Melman | O2: Żuczek
A3: 41308 | B3: Łódzkie | C3: NFZ | D3: Maurycy | E3: Tęcza | F3: 1058.55 | H3: Burza | I3: =SUMIFS($F$2:$F$1777,$E$2:$E$1777,$H3,$D$2:$D$1777,I$2) -> 47535.65 | J3: =SUMIFS($F$2:$F$1777,$E$2:$E$1777,$H3,$D$2:$D$1777,J$2) -> 71308.05 | K3: =SUMIFS($F$2:$F$1777,$E$2:$E$1777,$H3,$D$2:$D$1777,K$2) -> 60058.35 | L3: =SUMIFS($F$2:$F$1777,$E$2:$E$1777,$H3,$D$2:$D$1777,L$2) -> 80446 | O3: Motylek
A4: 41416 | B4: Warmińsko-mazurskie | C4: McDonald's | D4: Melman | E4: Burza | F4: 1820.6 | H4: Chmura | I4: =SUMIFS($F$2:$F$1777,$E$2:$E$1777,$H4,$D$2:$D$1777,I$2) -> 64885.1 | J4: =SUMIFS($F$2:$F$1777,$E$2:$E$1777,$H4,$D$2:$D$1777,J$2) -> 72880.4 | K4: =SUMIFS($F$2:$F$1777,$E$2:$E$1777,$H4,$D$2:$D$1777,K$2) -> 56261.8 | L4: =SUMIFS($F$2:$F$1777,$E$2:$E$1777,$H4,$D$2:$D$1777,L$2) -> 76584.2 | O4: Mrówka
A5: 41440 | B5: Kujawsko-pomorskie | C5: BNI | D5: Aleks | E5: Burza | F5: 1000 | H5: Deszcz | I5: =SUMIFS($F$2:$F$1777,$E$2:$E$1777,$H5,$D$2:$D$1777,I$2) -> 51138.85 | J5: =SUMIFS($F$2:$F$1777,$E$2:$E$1777,$H5,$D$2:$D$1777,J$2) -> 62025.2 | K5: =SUMIFS($F$2:$F$1777,$E$2:$E$1777,$H5,$D$2:$D$1777,K$2) -> 67472.75 | L5: =SUMIFS($F$2:$F$1777,$E$2:$E$1777,$H5,$D$2:$D$1777,L$2) -> 65445.35 | O5: Stonoga
A6: 41373 | B6: Zachodniopomorskie | C6: Coca-Cola | D6: Aleks | E6: Grom | F6: 488.75 | H6: Grad | I6: =SUMIFS($F$2:$F$1777,$E$2:$E$1777,$H6,$D$2:$D$1777,I$2) -> 78027.05 | J6: =SUMIFS($F$2:$F$1777,$E$2:$E$1777,$H6,$D$2:$D$1777,J$2) -> 57439.3 | K6: =SUMIFS($F$2:$F$1777,$E$2:$E$1777,$H6,$D$2:$D$1777,K$2) -> 67576.3 | L6: =SUMIFS($F$2:$F$1777,$E$2:$E$1777,$H6,$D$2:$D$1777,L$2) -> 73876.85
A7: 41415 | B7: Mazowieckie | C7: Pepsi | D7: Aleks | E7: Chmura | F7: 134.35 | H7: Grom | I7: =SUMIFS($F$2:$F$1777,$E$2:$E$1777,$H7,$D$2:$D$1777,I$2) -> 78691.7 | J7: =SUMIFS($F$2:$F$1777,$E$2:$E$1777,$H7,$D$2:$D$1777,J$2) -> 62824 | K7: =SUMIFS($F$2:$F$1777,$E$2:$E$1777,$H7,$D$2:$D$1777,K$2) -> 45902.35 | L7: =SUMIFS($F$2:$F$1777,$E$2:$E$1777,$H7,$D$2:$D$1777,L$2) -> 71288.8
A8: 41403 | B8: Dolnośląskie | C8: McDonald's | D8: Melman | E8: Grom | F8: 1264.75 | H8: Słońce | I8: =SUMIFS($F$2:$F$1777,$E$2:$E$1777,$H8,$D$2:$D$1777,I$2) -> 79268.25 | J8: =SUMIFS($F$2:$F$1777,$E$2:$E$1777,$H8,$D$2:$D$1777,J$2) -> 75534.65 | K8: =SUMIFS($F$2:$F$1777,$E$2:$E$1777,$H8,$D$2:$D$1777,K$2) -> 64633.8 | L8: =SUMIFS($F$2:$F$1777,$E$2:$E$1777,$H8,$D$2:$D$1777,L$2) -> 67572.2
A9: 41353 | B9: Kujawsko-pomorskie | C9: USB | D9: Aleks | E9: Chmura | F9: 219.3 | H9: Tęcza | I9: =SUMIFS($F$2:$F$1777,$E$2:$E$1777,$H9,$D$2:$D$1777,I$2) -> 54533 | J9: =SUMIFS($F$2:$F$1777,$E$2:$E$1777,$H9,$D$2:$D$1777,J$2) -> 67602.8 | K9: =SUMIFS($F$2:$F$1777,$E$2:$E$1777,$H9,$D$2:$D$1777,K$2) -> 77134.3 | L9: =SUMIFS($F$2:$F$1777,$E$2:$E$1777,$H9,$D$2:$D$1777,L$2) -> 74816.1
A10: 41436 | B10: Zachodniopomorskie | C10: Pepsi | D10: Aleks | E10: Deszcz | F10: 1310.3
A11: 41306 | B11: Świętokrzyskie | C11: Sygnity | D11: Melman | E11: Burza | F11: 372.1
A12: 41362 | B12: Małopolskie | C12: Mac | D12: Gloria | E12: Grad | F12: 837.75 | H12: Suma z Sprzedaż | I12: Etykiety kolumn
A13: 41391 | B13: Śląskie | C13: ZPP | D13: Maurycy | E13: Słońce | F13: 1397.25 | H13: Etykiety wierszy | I13: Aleks | J13: Gloria | K13: Maurycy | L13: Melman
A14: 41428 | B14: Mazowieckie | C14: Microsoft | D14: Aleks | E14: Słońce | F14: 217.35 | H14: Burza | I14: 47535.65 | J14: 71308.05 | K14: 60058.35 | L14: 80446
A15: 41361 | B15: Warmińsko-mazurskie | C15: Coca-Cola | D15: Aleks | E15: Grad | F15: 1415.15 | H15: Chmura | I15: 64885.1 | J15: 72880.4 | K15: 56261.8 | L15: 76584.2
A16: 41449 | B16: Lubelskie | C16: USB | D16: Aleks | E16: Grad | F16: 144.25 | H16: Deszcz | I16: 51138.85 | J16: 62025.2 | K16: 67472.75 | L16: 65445.35
A17: 41286 | B17: Podkarpackie | C17: ZUS | D17: Melman | E17: Tęcza | F17: 1471.15 | H17: Grad | I17: 78027.05 | J17: 57439.3 | K17: 67576.3 | L17: 73876.85
A18: 41441 | B18: Małopolskie | C18: YouTube | D18: Aleks | E18: Deszcz | F18: 440.5 | H18: Grom | I18: 78691.7 | J18: 62824 | K18: 45902.35 | L18: 71288.8
A19: 41380 | B19: Łódzkie | C19: VAT | D19: Maurycy | E19: Grad | F19: 104.9 | H19: Słońce | I19: 79268.25 | J19: 75534.65 | K19: 64633.8 | L19: 67572.2
A20: 41442 | B20: Wielkopolskie | C20: PKO SA | D20: Melman | E20: Słońce | F20: 1254.3 | H20: Tęcza | I20: 54533 | J20: 67602.8 | K20: 77134.3 | L20: 74816.1
A21: 41383 | B21: Mazowieckie | C21: Mac | D21: Melman | E21: Słońce | F21: 858.1
A22: 41392 | B22: Wielkopolskie | C22: PKO SA | D22: Gloria | E22: Grad | F22: 1689.3
A23: 41428 | B23: Śląskie | C23: YouTube | D23: Aleks | E23: Grom | F23: 976.95
A24: 41313 | B24: Małopolskie | C24: ZPP | D24: Aleks | E24: Grom | F24: 206.7
A25: 41378 | B25: Kujawsko-pomorskie | C25: Comarch | D25: Melman | E25: Tęcza | F25: 1143.1
A26: 41390 | B26: Lubelskie | C26: USB | D26: Aleks | E26: Chmura | F26: 896.45
A27: 41390 | B27: Śląskie | C27: PKO BP | D27: Maurycy | E27: Słońce | F27: 1499.85
A28: 41360 | B28: Kujawsko-pomorskie | C28: US | D28: Gloria | E28: Tęcza | F28: 267.45
A29: 41354 | B29: Lubuskie | C29: YouTube | D29: Gloria | E29: Słońce | F29: 643.65
A30: 41335 | B30: Wielkopolskie | C30: NFZ | D30: Gloria | E30: Grom | F30: 848.3
A31: 41351 | B31: Mazowieckie | C31: YouTube | D31: Aleks | E31: Grom | F31: 1551.95
A32: 41434 | B32: Podkarpackie | C32: USB | D32: Aleks | E32: Słońce | F32: 1426.5
... A1777: 41350 | B1777: Dolnośląskie | C1777: VAT | D1777: Aleks | E1777: Słońce | F1777: 1314.25

Sheet Arkusz1
A1: Data | B1: Sprzedawca | C1: Województwo | D1: Produkt | E1: Ilość | F1: Cena | G1: Wartość
A2: 42175 | B2: Abis Mal | C2: Lubelskie | D2: Błazenek | E2: 12 | F2: 2.5 | G2: 30
A3: 42132 | B3: Abis Mal | C3: Lubelskie | D3: Błazenek | E3: 19 | F3: 2.5 | G3: 47.5
A4: 42113 | B4: Abis Mal | C4: Lubelskie | D4: Błazenek | E4: 5 | F4: 2.5 | G4: 12.5
A5: 42231 | B5: Abis Mal | C5: Lubelskie | D5: Błazenek | E5: 12 | F5: 2.5 | G5: 30
A6: 42202 | B6: Abis Mal | C6: Lubelskie | D6: Błazenek | E6: 4 | F6: 2.5 | G6: 10
A7: 42058 | B7: Abis Mal | C7: Lubelskie | D7: Błazenek | E7: 13 | F7: 2.5 | G7: 32.5
A8: 42233 | B8: Abis Mal | C8: Lubelskie | D8: Błazenek | E8: 6 | F8: 2.5 | G8: 15

Sheet Układy
A1: Data | B1: Sprzedawca | C1: Województwo | D1: Produkt | E1: Ilość | F1: Cena | G1: Wartość
A2: 42338 | B2: Jago | C2: Świętokrzyskie | D2: Muszelki 3 | E2: 5 | F2: 4 | G2: 20
A3: 42132 | B3: Abis Mal | C3: Lubelskie | D3: Błazenek | E3: 19 | F3: 2.5 | G3: 47.5 | I3: Suma z Wartość | K3: Sprzedawca
A4: 42359 | B4: Alladyn | C4: Mazowieckie | D4: Błazenek | E4: 20 | F4: 2.5 | G4: 50 | I4: Województwo | J4: Produkt | K4: Abu | L4: Jago | M4: Alladyn | N4: Abis Mal | O4: Jasmina | P4: Suma końcowa
A5: 42340 | B5: Jasmina | C5: Mazowieckie | D5: Muszelki 1 | E5: 12 | F5: 2 | G5: 24 | I5: Lubelskie | J5: Gąbki | K5: *** | L5: 57.5 | M5: 21.5 | N5: 46 | O5: 42 | P5: 167
A6: 42356 | B6: Jasmina | C6: Mazowieckie | D6: Żółwik | E6: 20 | F6: 5 | G6: 100 | J6: Piasek | K6: 3.5 | L6: 6.1 | M6: 4.5 | N6: *** | O6: 14.6 | P6: 28.7
A7: 42035 | B7: Jasmina | C7: Lubelskie | D7: Gąbki | E7: 16 | F7: 0.5 | G7: 8 | J7: Wodorosty | K7: 20 | L7: 14.2 | M7: 13.4 | N7: 5.6 | O7: *** | P7: 53.2
A8: 42249 | B8: Abu | C8: Lubelskie | D8: Piasek | E8: 2 | F8: 0.1 | G8: 0.2 | J8: Muszelki 1 | K8: 54 | L8: 174 | M8: 206 | N8: 174 | O8: 102 | P8: 710
A9: 42022 | B9: Alladyn | C9: Świętokrzyskie | D9: Wodorosty | E9: 4 | F9: 0.2 | G9: 0.8 | J9: Muszelki 2 | K9: 91.5 | L9: 133.5 | M9: 142.5 | N9: 81 | O9: 60 | P9: 508.5
A10: 42031 | B10: Alladyn | C10: Wielkopolskie | D10: Piasek | E10: 4 | F10: 0.1 | G10: 0.4 | J10: Błazenek | K10: 200 | L10: *** | M10: 232.5 | N10: 177.5 | O10: 132.5 | P10: 742.5
A11: 42174 | B11: Abu | C11: Wielkopolskie | D11: Muszelki 3 | E11: 18 | F11: 4 | G11: 72 | J11: Żółwik | K11: 285 | L11: 420 | M11: 230 | N11: 95 | O11: 575 | P11: 1605
A12: 42050 | B12: Jasmina | C12: Wielkopolskie | D12: Muszelki 2 | E12: 15 | F12: 1.5 | G12: 22.5 | J12: Muszelki 3 | K12: 496 | L12: 184 | M12: *** | N12: 216 | O12: 448 | P12: 1344
A13: 42298 | B13: Alladyn | C13: Wielkopolskie | D13: Wodorosty | E13: 4 | F13: 0.2 | G13: 0.8 | I13: Lubelskie Suma | K13: 1150 | L13: 989.3 | M13: 850.4 | N13: 795.1 | O13: 1374.1 | P13: 5158.9
A14: 42360 | B14: Abu | C14: Lubelskie | D14: Muszelki 3 | E14: 6 | F14: 4 | G14: 24 | I14: Łódzkie | J14: Gąbki | K14: *** | L14: 26 | M14: 11 | N14: 41 | O14: 55.5 | P14: 133.5
A15: 42147 | B15: Abu | C15: Lubelskie | D15: Żółwik | E15: 6 | F15: 5 | G15: 30 | J15: Piasek | K15: 5.2 | L15: 4.3 | M15: 1.9 | N15: *** | O15: 6.1 | P15: 17.5
A16: 42052 | B16: Abis Mal | C16: Mazowieckie | D16: Muszelki 1 | E16: 18 | F16: 2 | G16: 36 | J16: Wodorosty | K16: 5.4 | L16: 14.8 | M16: 16 | N16: 3.8 | O16: *** | P16: 40
A17: 42071 | B17: Jasmina | C17: Świętokrzyskie | D17: Muszelki 3 | E17: 2 | F17: 4 | G17: 8 | J17: Muszelki 2 | K17: 9 | L17: 82.5 | M17: 45 | N17: 34.5 | O17: 117 | P17: 288
A18: 42087 | B18: Jasmina | C18: Lubelskie | D18: Piasek | E18: 11 | F18: 0.1 | G18: 1.1 | J18: Muszelki 1 | K18: 112 | L18: 122 | M18: 300 | N18: 46 | O18: 58 | P18: 638
A19: 42050 | B19: Jago | C19: Lubelskie | D19: Piasek | E19: 12 | F19: 0.1 | G19: 1.2 | J19: Błazenek | K19: 265 | L19: *** | M19: 95 | N19: 50 | O19: 120 | P19: 530
A20: 42264 | B20: Jasmina | C20: Lubelskie | D20: Żółwik | E20: 1 | F20: 5 | G20: 5 | J20: Żółwik | K20: 345 | L20: 345 | M20: 260 | N20: 140 | O20: 355 | P20: 1445
A21: 42202 | B21: Abis Mal | C21: Wielkopolskie | D21: Muszelki 2 | E21: 10 | F21: 1.5 | G21: 15 | J21: Muszelki 3 | K21: 424 | L21: 464 | M21: *** | N21: 396 | O21: 248 | P21: 1532
A22: 42049 | B22: Abu | C22: Wielkopolskie | D22: Żółwik | E22: 14 | F22: 5 | G22: 70 | I22: Łódzkie Suma | K22: 1165.6 | L22: 1058.6 | M22: 728.9 | N22: 711.3 | O22: 959.6 | P22: 4624
A23: 42096 | B23: Abis Mal | C23: Łódzkie | D23: Muszelki 3 | E23: 14 | F23: 4 | G23: 56 | I23: Mazowieckie | J23: Piasek | K23: 7.4 | L23: 6.2 | M23: 5.8 | N23: *** | O23: 8.5 | P23: 27.9
A24: 42010 | B24: Jago | C24: Świętokrzyskie | D24: Muszelki 3 | E24: 13 | F24: 4 | G24: 52 | J24: Gąbki | K24: 10 | L24: 29 | M24: 30.5 | N24: 37.5 | O24: 27 | P24: 134
A25: 42066 | B25: Jago | C25: Mazowieckie | D25: Muszelki 1 | E25: 13 | F25: 2 | G25: 26 | J25: Wodorosty | K25: 10.8 | L25: 14 | M25: 10.4 | N25: 9.4 | O25: *** | P25: 44.6
A26: 42240 | B26: Abis Mal | C26: Wielkopolskie | D26: Muszelki 1 | E26: 4 | F26: 2 | G26: 8 | J26: Błazenek | K26: 95 | L26: *** | M26: 117.5 | N26: 132.5 | O26: 220 | P26: 565
A27: 42249 | B27: Abis Mal | C27: Wielkopolskie | D27: Muszelki 1 | E27: 3 | F27: 2 | G27: 6 | J27: Muszelki 2 | K27: 112.5 | L27: 81 | M27: 43.5 | N27: 84 | O27: 73.5 | P27: 394.5
A28: 42249 | B28: Abu | C28: Łódzkie | D28: Błazenek | E28: 17 | F28: 2.5 | G28: 42.5 | J28: Muszelki 1 | K28: 132 | L28: 124 | M28: 142 | N28: 212 | O28: 166 | P28: 776
A29: 42258 | B29: Jasmina | C29: Łódzkie | D29: Żółwik | E29: 18 | F29: 5 | G29: 90 | J29: Żółwik | K29: 275 | L29: 225 | M29: 160 | N29: 95 | O29: 400 | P29: 1155
A30: 42369 | B30: Abu | C30: Świętokrzyskie | D30: Piasek | E30: 4 | F30: 0.1 | G30: 0.4 | J30: Muszelki 3 | K30: 328 | L30: 416 | M30: *** | N30: 412 | O30: 392 | P30: 1548
A31: 42348 | B31: Abis Mal | C31: Wielkopolskie | D31: Żółwik | E31: 13 | F31: 5 | G31: 65 | I31: Mazowieckie Suma | K31: 970.7 | L31: 895.2 | M31: 509.7 | N31: 982.4 | O31: 1287 | P31: 4645
A32: 42287 | B32: Jasmina | C32: Świętokrzyskie | D32: Muszelki 1 | E32: 1 | F32: 2 | G32: 2 | I32: Świętokrzyskie | J32: Gąbki | K32: 8.5 | L32: 37 | M32: 29 | N32: 36.5 | O32: 38 | P32: 149
A33: 42350 | B33: Alladyn | C33: Wielkopolskie | D33: Muszelki 2 | E33: 6 | F33: 1.5 | G33: 9 | J33: Piasek | K33: 9.8 | L33: 4 | M33: 4.4 | N33: *** | O33: 7.7 | P33: 25.9
A34: 42198 | B34: Jasmina | C34: Lubelskie | D34: Żółwik | E34: 13 | F34: 5 | G34: 65 | J34: Wodorosty | K34: 11 | L34: 13.6 | M34: 12.6 | N34: 16.4 | O34: *** | P34: 53.6
A35: 42271 | B35: Abis Mal | C35: Wielkopolskie | D35: Gąbki | E35: 11 | F35: 0.5 | G35: 5.5 | J35: Muszelki 2 | K35: 58.5 | L35: 120 | M35: 46.5 | N35: 66 | O35: 69 | P35: 360
A36: 42248 | B36: Abu | C36: Świętokrzyskie | D36: Muszelki 3 | E36: 10 | F36: 4 | G36: 40 | J36: Muszelki 1 | K36: 68 | L36: 108 | M36: 78 | N36: 130 | O36: 164 | P36: 548
A37: 42320 | B37: Jasmina | C37: Łódzkie | D37: Muszelki 3 | E37: 13 | F37: 4 | G37: 52 | J37: Błazenek | K37: 245 | L37: *** | M37: 120 | N37: 152.5 | O37: 215 | P37: 732.5
A38: 42019 | B38: Jago | C38: Mazowieckie | D38: Piasek | E38: 2 | F38: 0.1 | G38: 0.2 | J38: Żółwik | K38: 275 | L38: 345 | M38: 320 | N38: 315 | O38: 335 | P38: 1590
A39: 42125 | B39: Abu | C39: Lubelskie | D39: Muszelki 1 | E39: 7 | F39: 2 | G39: 14 | J39: Muszelki 3 | K39: 388 | L39: 664 | M39: *** | N39: 48 | O39: 132 | P39: 1232
A40: 42312 | B40: Abis Mal | C40: Łódzkie | D40: Muszelki 1 | E40: 7 | F40: 2 | G40: 14 | I40: Świętokrzyskie Suma | K40: 1063.8 | L40: 1291.6 | M40: 610.5 | N40: 764.4 | O40: 960.7 | P40: 4691
...

Sheet Daty
A1: Data | B1: Województwo | C1: Klient | D1: Sprzedawca | E1: Produkt | F1: Sprzedaż | G1: KWS | I1: Suma sprzedaż
A2: 41311 | B2: Dolnośląskie | C2: US | D2: Melman | E2: Słońce | F2: 1677.5 | G2: 886.85 | I2: Miesiąc/Sprzedawca | J2: Alex | K2: Gloria | L2: Marty | M2: Melman
A3: 41308 | B3: Łódzkie | C3: NFZ | D3: Marty | E3: Tęcza | F3: 1058.55 | G3: 720.25 | I3: sty | J3: =SUMIFS($F$2:$F$1777,$D$2:$D$1777,J$2,$A$2:$A$1777,">=1"&$I3&2013,$A$2:$A$1777,"<="&EOMONTH("1"&$I3&2013,0)) -> 78410.6 | K3: =SUMIFS($F$2:$F$1777,$D$2:$D$1777,K$2,$A$2:$A$1777,">=1"&$I3&2013,$A$2:$A$1777,"<="&EOMONTH("1"&$I3&2013,0)) -> 84417 | L3: =SUMIFS($F$2:$F$1777,$D$2:$D$1777,L$2,$A$2:$A$1777,">=1"&$I3&2013,$A$2:$A$1777,"<="&EOMONTH("1"&$I3&2013,0)) -> 66174.1 | M3: =SUMIFS($F$2:$F$1777,$D$2:$D$1777,M$2,$A$2:$A$1777,">=1"&$I3&2013,$A$2:$A$1777,"<="&EOMONTH("1"&$I3&2013,0)) -> 83513.15
A4: 41416 | B4: Warmińsko-mazurskie | C4: McDonald's | D4: Melman | E4: Burza | F4: 1820.6 | G4: 549.9 | I4: lut | J4: =SUMIFS($F$2:$F$1777,$D$2:$D$1777,J$2,$A$2:$A$1777,">=1"&$I4&2013,$A$2:$A$1777,"<="&EOMONTH("1"&$I4&2013,0)) -> 44401.1 | K4: =SUMIFS($F$2:$F$1777,$D$2:$D$1777,K$2,$A$2:$A$1777,">=1"&$I4&2013,$A$2:$A$1777,"<="&EOMONTH("1"&$I4&2013,0)) -> 76707 | L4: =SUMIFS($F$2:$F$1777,$D$2:$D$1777,L$2,$A$2:$A$1777,">=1"&$I4&2013,$A$2:$A$1777,"<="&EOMONTH("1"&$I4&2013,0)) -> 83697.25 | M4: =SUMIFS($F$2:$F$1777,$D$2:$D$1777,M$2,$A$2:$A$1777,">=1"&$I4&2013,$A$2:$A$1777,"<="&EOMONTH("1"&$I4&2013,0)) -> 64747.65
A5: 41440 | B5: Kujawsko-pomorskie | C5: BNI | D5: Alex | E5: Burza | F5: 1695.35 | G5: 882.45 | I5: mar | J5: =SUMIFS($F$2:$F$1777,$D$2:$D$1777,J$2,$A$2:$A$1777,">=1"&$I5&2013,$A$2:$A$1777,"<="&EOMONTH("1"&$I5&2013,0)) -> 84651.55 | K5: =SUMIFS($F$2:$F$1777,$D$2:$D$1777,K$2,$A$2:$A$1777,">=1"&$I5&2013,$A$2:$A$1777,"<="&EOMONTH("1"&$I5&2013,0)) -> 92017.1 | L5: =SUMIFS($F$2:$F$1777,$D$2:$D$1777,L$2,$A$2:$A$1777,">=1"&$I5&2013,$A$2:$A$1777,"<="&EOMONTH("1"&$I5&2013,0)) -> 82483.05 | M5: =SUMIFS($F$2:$F$1777,$D$2:$D$1777,M$2,$A$2:$A$1777,">=1"&$I5&2013,$A$2:$A$1777,"<="&EOMONTH("1"&$I5&2013,0)) -> 98366.4
A6: 41373 | B6: Zachodniopomorskie | C6: Coca-Cola | D6: Alex | E6: Grom | F6: 488.75 | G6: 261.35 | I6: kwi | J6: =SUMIFS($F$2:$F$1777,$D$2:$D$1777,J$2,$A$2:$A$1777,">=1"&$I6&2013,$A$2:$A$1777,"<="&EOMONTH("1"&$I6&2013,0)) -> 77142.75 | K6: =SUMIFS($F$2:$F$1777,$D$2:$D$1777,K$2,$A$2:$A$1777,">=1"&$I6&2013,$A$2:$A$1777,"<="&EOMONTH("1"&$I6&2013,0)) -> 69392.1 | L6: =SUMIFS($F$2:$F$1777,$D$2:$D$1777,L$2,$A$2:$A$1777,">=1"&$I6&2013,$A$2:$A$1777,"<="&EOMONTH("1"&$I6&2013,0)) -> 65837.15 | M6: =SUMIFS($F$2:$F$1777,$D$2:$D$1777,M$2,$A$2:$A$1777,">=1"&$I6&2013,$A$2:$A$1777,"<="&EOMONTH("1"&$I6&2013,0)) -> 77578.1
A7: 41415 | B7: Mazowieckie | C7: Pepsi | D7: Alex | E7: Chmura | F7: 134.35 | G7: 73.2 | I7: maj | J7: =SUMIFS($F$2:$F$1777,$D$2:$D$1777,J$2,$A$2:$A$1777,">=1"&$I7&2013,$A$2:$A$1777,"<="&EOMONTH("1"&$I7&2013,0)) -> 90200.6 | K7: =SUMIFS($F$2:$F$1777,$D$2:$D$1777,K$2,$A$2:$A$1777,">=1"&$I7&2013,$A$2:$A$1777,"<="&EOMONTH("1"&$I7&2013,0)) -> 81280.65 | L7: =SUMIFS($F$2:$F$1777,$D$2:$D$1777,L$2,$A$2:$A$1777,">=1"&$I7&2013,$A$2:$A$1777,"<="&EOMONTH("1"&$I7&2013,0)) -> 83423.3 | M7: =SUMIFS($F$2:$F$1777,$D$2:$D$1777,M$2,$A$2:$A$1777,">=1"&$I7&2013,$A$2:$A$1777,"<="&EOMONTH("1"&$I7&2013,0)) -> 81345.75
A8: 41403 | B8: Dolnośląskie | C8: McDonald's | D8: Melman | E8: Grom | F8: 1264.75 | G8: 343.9 | I8: cze | J8: =SUMIFS($F$2:$F$1777,$D$2:$D$1777,J$2,$A$2:$A$1777,">=1"&$I8&2013,$A$2:$A$1777,"<="&EOMONTH("1"&$I8&2013,0)) -> 79968.35 | K8: =SUMIFS($F$2:$F$1777,$D$2:$D$1777,K$2,$A$2:$A$1777,">=1"&$I8&2013,$A$2:$A$1777,"<="&EOMONTH("1"&$I8&2013,0)) -> 65800.55 | L8: =SUMIFS($F$2:$F$1777,$D$2:$D$1777,L$2,$A$2:$A$1777,">=1"&$I8&2013,$A$2:$A$1777,"<="&EOMONTH("1"&$I8&2013,0)) -> 57424.8 | M8: =SUMIFS($F$2:$F$1777,$D$2:$D$1777,M$2,$A$2:$A$1777,">=1"&$I8&2013,$A$2:$A$1777,"<="&EOMONTH("1"&$I8&2013,0)) -> 104478.45
A9: 41353 | B9: Kujawsko-pomorskie | C9: USB | D9: Alex | E9: Chmura | F9: 219.3 | G9: 94.9
A10: 41436 | B10: Zachodniopomorskie | C10: Pepsi | D10: Alex | E10: Deszcz | F10: 1310.3 | G10: 487.5
A11: 41306 | B11: Świętokrzyskie | C11: Sygnity | D11: Melman | E11: Burza | F11: 372.1 | G11: 205 | I11: Suma z Sprzedaż | J11: Etykiety kolumn
A12: 41362 | B12: Małopolskie | C12: Mac | D12: Gloria | E12: Grad | F12: 837.75 | G12: 437.6 | I12: Etykiety wierszy | J12: Alex | K12: Gloria | L12: Marty | M12: Melman | N12: Suma końcowa
A13: 41391 | B13: Śląskie | C13: ZPP | D13: Marty | E13: Słońce | F13: 1397.25 | G13: 568.85 | I13: sty | J13: 78410.6 | K13: 84417 | L13: 66174.1 | M13: 83513.15 | N13: 312514.85
A14: 41428 | B14: Mazowieckie | C14: Microsoft | D14: Alex | E14: Słońce | F14: 217.35 | G14: 105.25 | I14: lut | J14: 44401.1 | K14: 76707 | L14: 83697.25 | M14: 64747.65 | N14: 269553
A15: 41361 | B15: Warmińsko-mazurskie | C15: Coca-Cola | D15: Alex | E15: Grad | F15: 1415.15 | G15: 785 | I15: mar | J15: 84651.55 | K15: 92017.1 | L15: 82483.05 | M15: 98366.4 | N15: 357518.1
A16: 41449 | B16: Lubelskie | C16: USB | D16: Alex | E16: Grad | F16: 144.25 | G16: 51.75 | I16: kwi | J16: 77142.75 | K16: 69392.1 | L16: 65837.15 | M16: 77578.1 | N16: 289950.1
A17: 41286 | B17: Podkarpackie | C17: ZUS | D17: Melman | E17: Tęcza | F17: 1471.15 | G17: 573.85 | I17: maj | J17: 90200.6 | K17: 81280.65 | L17: 83423.3 | M17: 81345.75 | N17: 336250.3
A18: 41441 | B18: Małopolskie | C18: YouTube | D18: Alex | E18: Deszcz | F18: 440.5 | G18: 244.95 | I18: cze | J18: 79968.35 | K18: 65800.55 | L18: 57424.8 | M18: 104478.45 | N18: 307672.15
A19: 41380 | B19: Łódzkie | C19: VAT | D19: Marty | E19: Grad | F19: 104.9 | G19: 61.3 | I19: Suma końcowa | J19: 454774.95 | K19: 469614.4 | L19: 439039.65 | M19: 510029.5 | N19: 1873458.5
A20: 41442 | B20: Wielkopolskie | C20: PKO SA | D20: Melman | E20: Słońce | F20: 1254.3 | G20: 420.25
A21: 41383 | B21: Mazowieckie | C21: Mac | D21: Melman | E21: Słońce | F21: 858.1 | G21: 552.9
A22: 41392 | B22: Wielkopolskie | C22: PKO SA | D22: Gloria | E22: Grad | F22: 1689.3 | G22: 779.5
A23: 41428 | B23: Śląskie | C23: YouTube | D23: Alex | E23: Grom | F23: 976.95 | G23: 487.45
A24: 41313 | B24: Małopolskie | C24: ZPP | D24: Alex | E24: Grom | F24: 206.7 | G24: 140.2
A25: 41378 | B25: Kujawsko-pomorskie | C25: Comarch | D25: Melman | E25: Tęcza | F25: 1143.1 | G25: 754.35
A26: 41390 | B26: Lubelskie | C26: USB | D26: Alex | E26: Chmura | F26: 896.45 | G26: 622.75
A27: 41390 | B27: Śląskie | C27: PKO BP | D27: Marty | E27: Słońce | F27: 1499.85 | G27: 633.6
A28: 41360 | B28: Kujawsko-pomorskie | C28: US | D28: Gloria | E28: Tęcza | F28: 267.45 | G28: 155.5
A29: 41354 | B29: Lubuskie | C29: YouTube | D29: Gloria | E29: Słońce | F29: 643.65 | G29: 398.8
A30: 41335 | B30: Wielkopolskie | C30: NFZ | D30: Gloria | E30: Grom | F30: 848.3 | G30: 358.6
A31: 41351 | B31: Mazowieckie | C31: YouTube | D31: Alex | E31: Grom | F31: 1551.95 | G31: 457.75
... A1777: 41350 | B1777: Dolnośląskie | C1777: VAT | D1777: Alex | E1777: Słońce | F1777: 1314.25 | G1777: 708

Sheet Liczby
A1: Data | B1: Sprzedawca | C1: Województwo | D1: Produkt | E1: Ilość | F1: Cena | G1: Sprzedaż
A2: 41510 | B2: Alladyn | C2: Wielkopolskie | D2: Żółwik | E2: 17 | F2: 5 | G2: =E2*F2 -> 85 | I2: Etykiety wierszy | J2: Suma z Sprzedaż
A3: 41560 | B3: Jago | C3: Wielkopolskie | D3: Muszelki 3 | E3: 54 | F3: 4 | G3: =E3*F3 -> 216 | I3: <30 | J3: 1853.4
A4: 41452 | B4: Abis Mal | C4: Łódzkie | D4: Wodorosty | E4: 81 | F4: 0.2 | G4: =E4*F4 -> 16.2 | I4: 30-59 | J4: 6295.3
A5: 41455 | B5: Jasmina | C5: Mazowieckie | D5: Muszelki 3 | E5: 115 | F5: 4 | G5: =E5*F5 -> 460 | I5: 60-89 | J5: 9879.5
A6: 41456 | B6: Abis Mal | C6: Świętokrzyskie | D6: Muszelki 3 | E6: 133 | F6: 4 | G6: =E6*F6 -> 532 | I6: 90-120 | J6: 14775.2
A7: 41609 | B7: Jasmina | C7: Mazowieckie | D7: Błazenek | E7: 19 | F7: 2.5 | G7: =E7*F7 -> 47.5 | I7: >120 | J7: 16435.3
A8: 41427 | B8: Jago | C8: Łódzkie | D8: Żółwik | E8: 45 | F8: 5 | G8: =E8*F8 -> 225 | I8: Suma końcowa | J8: 49238.7
A9: 41496 | B9: Jago | C9: Mazowieckie | D9: Muszelki 2 | E9: 100 | F9: 1.5 | G9: 300
A10: 41507 | B10: Abis Mal | C10: Świętokrzyskie | D10: Gąbki | E10: 37 | F10: 0.5 | G10: =E10*F10 -> 18.5
A11: 41592 | B11: Alladyn | C11: Świętokrzyskie | D11: Piasek | E11: 85 | F11: 0.1 | G11: =E11*F11 -> 8.5
A12: 41498 | B12: Abis Mal | C12: Lubelskie | D12: Żółwik | E12: 30 | F12: 5 | G12: =E12*F12 -> 150 | I12: Etykiety wierszy | J12: Suma z Sprzedaż
A13: 41582 | B13: Jasmina | C13: Mazowieckie | D13: Piasek | E13: 118 | F13: 0.1 | G13: =E13*F13 -> 11.8 | I13: <100 | J13: 4738.7
A14: 41505 | B14: Abis Mal | C14: Lubelskie | D14: Muszelki 2 | E14: 108 | F14: 1.5 | G14: =E14*F14 -> 162 | I14: 100-300 | J14: 19701
A15: 41629 | B15: Alladyn | C15: Wielkopolskie | D15: Muszelki 2 | E15: 18 | F15: 1.5 | G15: =E15*F15 -> 27 | I15: 300-500 | J15: 12781
A16: 41439 | B16: Jasmina | C16: Wielkopolskie | D16: Muszelki 1 | E16: 84 | F16: 2 | G16: =E16*F16 -> 168 | I16: 500-700 | J16: 10533
A17: 41443 | B17: Jasmina | C17: Wielkopolskie | D17: Żółwik | E17: 64 | F17: 5 | G17: 100 | I17: >700 | J17: 1485
A18: 41572 | B18: Abis Mal | C18: Świętokrzyskie | D18: Muszelki 1 | E18: 29 | F18: 2 | G18: =E18*F18 -> 58 | I18: Suma końcowa | J18: 49238.7
A19: 41544 | B19: Jago | C19: Łódzkie | D19: Muszelki 2 | E19: 26 | F19: 1.5 | G19: =E19*F19 -> 39
A20: 41563 | B20: Jasmina | C20: Mazowieckie | D20: Muszelki 2 | E20: 148 | F20: 1.5 | G20: =E20*F20 -> 222
A21: 41595 | B21: Abis Mal | C21: Świętokrzyskie | D21: Wodorosty | E21: 13 | F21: 0.2 | G21: =E21*F21 -> 2.6
A22: 41589 | B22: Jago | C22: Wielkopolskie | D22: Muszelki 3 | E22: 107 | F22: 4 | G22: =E22*F22 -> 428
A23: 41479 | B23: Jago | C23: Świętokrzyskie | D23: Piasek | E23: 105 | F23: 0.1 | G23: 700
A24: 41523 | B24: Abis Mal | C24: Lubelskie | D24: Muszelki 2 | E24: 14 | F24: 1.5 | G24: =E24*F24 -> 21
A25: 41507 | B25: Jago | C25: Lubelskie | D25: Wodorosty | E25: 150 | F25: 0.2 | G25: =E25*F25 -> 30
A26: 41430 | B26: Alladyn | C26: Lubelskie | D26: Wodorosty | E26: 125 | F26: 0.2 | G26: =E26*F26 -> 25
A27: 41629 | B27: Alladyn | C27: Lubelskie | D27: Muszelki 3 | E27: 28 | F27: 4 | G27: =E27*F27 -> 112
A28: 41567 | B28: Abis Mal | C28: Świętokrzyskie | D28: Piasek | E28: 43 | F28: 0.1 | G28: =E28*F28 -> 4.3
A29: 41592 | B29: Jasmina | C29: Łódzkie | D29: Wodorosty | E29: 65 | F29: 0.2 | G29: =E29*F29 -> 13
A30: 41559 | B30: Jago | C30: Świętokrzyskie | D30: Muszelki 1 | E30: 59 | F30: 2 | G30: =E30*F30 -> 118
A31: 41576 | B31: Alladyn | C31: Świętokrzyskie | D31: Żółwik | E31: 82 | F31: 5 | G31: =E31*F31 -> 410
A32: 41431 | B32: Jago | C32: Świętokrzyskie | D32: Muszelki 2 | E32: 88 | F32: 1.5 | G32: =E32*F32 -> 132
A33: 41477 | B33: Alladyn | C33: Wielkopolskie | D33: Muszelki 3 | E33: 45 | F33: 4 | G33: =E33*F33 -> 180
A34: 41590 | B34: Abu | C34: Lubelskie | D34: Piasek | E34: 64 | F34: 0.1 | G34: =E34*F34 -> 6.4
A35: 41467 | B35: Jasmina | C35: Lubelskie | D35: Wodorosty | E35: 42 | F35: 0.2 | G35: =E35*F35 -> 8.4
... A325: 41554 | B325: Alladyn | C325: Łódzkie | D325: Błazenek | E325: 106 | F325: 2.5 | G325: =E325*F325 -> 265

Sheet Wiekowe
A1: Wiek | B1: Pyt1 | C1: Pyt2 | D1: Pyt3
A2: 39 | B2: TAK | C2: NIE | D2: TAK | F2: Pytanie 1 | G2: Etykiety kolumn
A3: 19 | B3: NIE | C3: NIE | D3: NIE | F3: Etykiety wierszy | G3: NIE | H3: TAK | I3: Suma końcowa
A4: 39 | B4: NIE | C4: NIE | D4: NIE | F4: 14-18
A5: 102 | B5: TAK | C5: NIE | D5: NIE | F5: 14 | G5: 1 | H5: 1 | I5: 2
A6: 16 | B6: TAK | C6: NIE | D6: NIE | F6: 15 | G6: 2 | I6: 2
A7: 16 | B7: NIE | C7: NIE | D7: TAK | F7: 16 | G7: 2 | H7: 2 | I7: 4
A8: 61 | B8: NIE | C8: NIE | D8: TAK | F8: 17 | G8: 1 | I8: 1
A9: 15 | B9: NIE | C9: TAK | D9: NIE | F9: 18 | H9: 1 | I9: 1
A10: 25 | B10: TAK | C10: NIE | D10: TAK | F10: 19-25 | G10: 7 | H10: 2 | I10: 9
A11: 14 | B11: TAK | C11: TAK | D11: NIE | F11: 26-35 | G11: 4 | H11: 6 | I11: 10
A12: 27 | B12: TAK | C12: TAK | D12: NIE | F12: 36-55 | G12: 9 | H12: 12 | I12: 21
A13: 102 | B13: TAK | C13: TAK | D13: TAK | F13: >55 | G13: 27 | H13: 22 | I13: 49
A14: 84 | B14: NIE | C14: TAK | D14: TAK | F14: Suma końcowa | G14: 53 | H14: 46 | I14: 99
A15: 43 | B15: TAK | C15: NIE | D15: TAK
A16: 80 | B16: NIE | C16: NIE | D16: TAK
A17: 49 | B17: TAK | C17: NIE | D17: NIE
A18: 82 | B18: NIE | C18: TAK | D18: TAK
A19: 15 | B19: NIE | C19: NIE | D19: TAK
A20: 49 | B20: TAK | C20: TAK | D20: TAK
A21: 17 | B21: NIE | C21: TAK | D21: TAK
A22: 76 | B22: TAK | C22: NIE | D22: TAK
A23: 61 | B23: NIE | C23: TAK | D23: NIE
A24: 31 | B24: TAK | C24: TAK | D24: NIE
A25: 71 | B25: TAK | C25: TAK | D25: NIE
A26: 29 | B26: TAK | C26: TAK | D26: NIE
... A100: 96 | B100: TAK | C100: NIE | D100: TAK

Sheet Tekst
A1: Data | B1: Sprzedawca | C1: Województwo | D1: Produkt | E1: Sprzedaż
A2: 42005 | B2: Karolina | C2: Świętokrzyskie | D2: Ementaler | E2: 16.81 | G2: Etykiety wierszy | H2: Suma z Sprzedaż
A3: 42005 | B3: Jan | C3: Łódzkie | D3: Jabłko | E3: 33.78 | G3: Warzywa
A4: 42005 | B4: Robert | C4: Świętokrzyskie | D4: Gruszka | E4: 65.7 | G4: Burak | H4: 10456.93
A5: 42005 | B5: Olga | C5: Dolnośląskie | D5: Jabłko | E5: 41.95 | G5: Marchewka | H5: 8811.77
A6: 42006 | B6: Robert | C6: Mazowieckie | D6: Jabłko | E6: 15 | G6: Pietruszka | H6: 9511.25
A7: 42006 | B7: Olga | C7: Małopolskie | D7: Ementaler | E7: 83.3 | G7: Sery
A8: 42006 | B8: Jan | C8: Świętokrzyskie | D8: Gruszka | E8: 44.93 | G8: Ementaler | H8: 9469.98
A9: 42006 | B9: Karolina | C9: Łódzkie | D9: Ementaler | E9: 63.75 | G9: Gouda | H9: 11304.04
A10: 42006 | B10: Karolina | C10: Łódzkie | D10: Gruszka | E10: 56.54 | G10: Owoce
A11: 42006 | B11: Jan | C11: Małopolskie | D11: Gouda | E11: 92.04 | G11: Gruszka | H11: 9382.8
A12: 42006 | B12: Karolina | C12: Dolnośląskie | D12: Gouda | E12: 48.45 | G12: Jabłko | H12: 9352.76
A13: 42007 | B13: Karolina | C13: Świętokrzyskie | D13: Gouda | E13: 35.65 | G13: Suma końcowa | H13: 68289.53
A14: 42008 | B14: Robert | C14: Mazowieckie | D14: Burak | E14: 69.81
A15: 42008 | B15: Olga | C15: Małopolskie | D15: Pietruszka | E15: 69.71
A16: 42009 | B16: Robert | C16: Dolnośląskie | D16: Gouda | E16: 26.56
A17: 42009 | B17: Robert | C17: Dolnośląskie | D17: Gruszka | E17: 65.5
A18: 42009 | B18: Jan | C18: Małopolskie | D18: Gouda | E18: 99.63
A19: 42009 | B19: Karolina | C19: Dolnośląskie | D19: Burak | E19: 95.86
A20: 42009 | B20: Olga | C20: Małopolskie | D20: Ementaler | E20: 87.35
A21: 42010 | B21: Robert | C21: Dolnośląskie | D21: Burak | E21: 13.83
A22: 42012 | B22: Olga | C22: Łódzkie | D22: Gouda | E22: 64.49
A23: 42012 | B23: Olga | C23: Łódzkie | D23: Gouda | E23: 120.25
A24: 42013 | B24: Olga | C24: Łódzkie | D24: Burak | E24: 92.09
A25: 42014 | B25: Jan | C25: Mazowieckie | D25: Marchewka | E25: 44.69
... A1001: 42369 | B1001: Robert | C1001: Łódzkie | D1001: Gruszka | E1001: 85.69

Sheet Analiza
A1: ID | B1: Pracownik | C1: Fabryka | D1: L. przepracowanych godzin w roku 2015 | F1: Etykiety wierszy | G1: Liczba Pracowników | H1: Suma | I1: Średnia | J1: OdchStd
A2: 842-7618 | B2: Marlin Błazenek | C2: Żuczek | D2: 2115 | F2: Motylek | G2: 14 | H2: 26353 | I2: 1882.3571 | J2: 170.60733
A3: 842-7728 | B3: Nemo Ryba | C3: Żuczek | D3: 1802 | F3: Ptaszek | G3: 16 | H3: 30590 | I3: 1911.875 | J3: 158.0434
A4: 842-5556 | B4: Dory Ultramarynka | C4: Ptaszek | D4: 2159 | F4: Stonoga | G4: 16 | H4: 29988 | I4: 1874.25 | J4: 145.86912
A5: 842-9509 | B5: Adam Kaufmann | C5: Motylek | D5: 1940 | F5: Żuczek | G5: 11 | H5: 20585 | I5: 1871.3636 | J5: 195.05962
A6: 842-3924 | B6: Piotr Pies | C6: Stonoga | D6: 1688 | F6: Suma końcowa | G6: 57 | H6: 107516 | I6: 1886.2456 | J6: 161.91734
A7: 842-5118 | B7: Beata Barwińska | C7: Motylek | D7: 1812
A8: 842-7777 | B8: Marlena Kotowska | C8: Stonoga | D8: 1875
A9: 842-7639 | B9: Atylla Chomik | C9: Ptaszek | D9: 1866
A10: 842-8497 | B10: Mindy Reżyser | C10: Stonoga | D10: 2162
A11: 842-1905 | B11: Melman Chory | C11: Ptaszek | D11: 2008
A12: 842-7903 | B12: Gloria Okrągła | C12: Stonoga | D12: 1821
A13: 842-2287 | B13: Brygida Węgrzynowska | C13: Motylek | D13: 1668
A14: 842-5078 | B14: Julian Ogoniasty | C14: Stonoga | D14: 1656
A15: 842-9774 | B15: Maurycy Poddany | C15: Ptaszek | D15: 2043
A16: 842-6544 | B16: Marian Noga | C16: Żuczek | D16: 2082
A17: 842-8756 | B17: Paulina Kot | C17: Ptaszek | D17: 1940
A18: 842-9805 | B18: Fiona Ogr | C18: Stonoga | D18: 1946
... A58: 842-1628 | B58: Beata Bończyk | C58: Ptaszek | D58: 1773

Sheet PokażJako
A1: Data | B1: Sprzedawca | C1: Województwo | D1: Produkt | E1: Ilość | F1: Cena | G1: Wartość
A2: 42240 | B2: Alladyn | C2: Wielkopolskie | D2: Żółwik | E2: 17 | F2: 5 | G2: =E2*F2 -> 85 | I2: Suma z Wartość | J2: Sprzedawca
A3: 42290 | B3: Jago | C3: Wielkopolskie | D3: Muszelki 3 | E3: 54 | F3: 4 | G3: =E3*F3 -> 216 | I3: Produkt | J3: Abis Mal | K3: Abu | L3: Alladyn | M3: Jago | N3: Jasmina | O3: Suma końcowa
A4: 42182 | B4: Abis Mal | C4: Łódzkie | D4: Wodorosty | E4: 81 | F4: 0.2 | G4: =E4*F4 -> 16.2 | I4: Błazenek | J4: 0.19094114 | K4: 0.16815839 | L4: 0.14239219 | M4: 0.30078655 | N4: 0.19772172 | O4: 1
A5: 42185 | B5: Jasmina | C5: Mazowieckie | D5: Muszelki 3 | E5: 115 | F5: 4 | G5: =E5*F5 -> 460 | I5: Gąbki | J5: 0.069508449 | K5: 0.10483871 | L5: 0.33486943 | M5: 0.32642089 | N5: 0.16436252 | O5: 1
A6: 42186 | B6: Abis Mal | C6: Świętokrzyskie | D6: Muszelki 3 | E6: 133 | F6: 4 | G6: =E6*F6 -> 532 | I6: Muszelki 1 | J6: 0.18225229 | K6: 0.10306407 | L6: 0.11460406 | M6: 0.26303223 | N6: 0.33704735 | O6: 1
A7: 42339 | B7: Jasmina | C7: Mazowieckie | D7: Błazenek | E7: 19 | F7: 2.5 | G7: =E7*F7 -> 47.5 | I7: Muszelki 2 | J7: 0.2721202 | K7: 0.11908737 | L7: 0.1427379 | M7: 0.2640512 | N7: 0.20200334 | O7: 1
A8: 42157 | B8: Jago | C8: Łódzkie | D8: Żółwik | E8: 45 | F8: 5 | G8: =E8*F8 -> 225 | I8: Muszelki 3 | J8: 0.17935212 | K8: 0.095075059 | L8: 0.27311035 | M8: 0.24598367 | N8: 0.2064788 | O8: 1
A9: 42226 | B9: Jago | C9: Mazowieckie | D9: Muszelki 2 | E9: 100 | F9: 1.5 | G9: =E9*F9 -> 150 | I9: Piasek | J9: 0.27252564 | K9: 0.081785417 | L9: 0.24701968 | M9: 0.16495703 | N9: 0.23371223 | O9: 1
A10: 42237 | B10: Abis Mal | C10: Świętokrzyskie | D10: Gąbki | E10: 37 | F10: 0.5 | G10: =E10*F10 -> 18.5 | I10: Wodorosty | J10: 0.21445783 | K10: 0.07439759 | L10: 0.17018072 | M10: 0.3373494 | N10: 0.20361446 | O10: 1
A11: 42322 | B11: Alladyn | C11: Świętokrzyskie | D11: Piasek | E11: 85 | F11: 0.1 | G11: =E11*F11 -> 8.5 | I11: Żółwik | J11: 0.023975588 | K11: 0.16434176 | L11: 0.22493461 | M11: 0.30078466 | N11: 0.28596338 | O11: 1
A12: 42228 | B12: Abis Mal | C12: Lubelskie | D12: Żółwik | E12: 30 | F12: 5 | G12: =E12*F12 -> 150 | I12: Suma końcowa | J12: 0.15370882 | K12: 0.12864054 | L12: 0.20617575 | M12: 0.27586838 | N12: 0.23560651 | O12: 1
A13: 42312 | B13: Jasmina | C13: Mazowieckie | D13: Piasek | E13: 118 | F13: 0.1 | G13: =E13*F13 -> 11.8
A14: 42235 | B14: Abis Mal | C14: Lubelskie | D14: Muszelki 2 | E14: 108 | F14: 1.5 | G14: =E14*F14 -> 162
A15: 42359 | B15: Alladyn | C15: Wielkopolskie | D15: Muszelki 2 | E15: 18 | F15: 1.5 | G15: =E15*F15 -> 27
A16: 42169 | B16: Jasmina | C16: Wielkopolskie | D16: Muszelki 1 | E16: 84 | F16: 2 | G16: =E16*F16 -> 168
A17: 42173 | B17: Jasmina | C17: Wielkopolskie | D17: Żółwik | E17: 64 | F17: 5 | G17: =E17*F17 -> 320
A18: 42302 | B18: Abis Mal | C18: Świętokrzyskie | D18: Muszelki 1 | E18: 29 | F18: 2 | G18: =E18*F18 -> 58
A19: 42274 | B19: Jago | C19: Łódzkie | D19: Muszelki 2 | E19: 26 | F19: 1.5 | G19: =E19*F19 -> 39
A20: 42293 | B20: Jasmina | C20: Mazowieckie | D20: Muszelki 2 | E20: 148 | F20: 1.5 | G20: =E20*F20 -> 222
A21: 42325 | B21: Abis Mal | C21: Świętokrzyskie | D21: Wodorosty | E21: 13 | F21: 0.2 | G21: =E21*F21 -> 2.6
A22: 42319 | B22: Jago | C22: Wielkopolskie | D22: Muszelki 3 | E22: 107 | F22: 4 | G22: =E22*F22 -> 428
A23: 42209 | B23: Jago | C23: Świętokrzyskie | D23: Piasek | E23: 105 | F23: 0.1 | G23: =E23*F23 -> 10.5
A24: 42253 | B24: Abis Mal | C24: Lubelskie | D24: Muszelki 2 | E24: 14 | F24: 1.5 | G24: =E24*F24 -> 21
... A325: 42284 | B325: Alladyn | C325: Łódzkie | D325: Błazenek | E325: 106 | F325: 2.5 | G325: =E325*F325 -> 265

Sheet PokażJako2
A1: Data | B1: Sprzedawca | C1: Województwo | D1: Produkt | E1: Ilość | F1: Cena | G1: Wartość
A2: 42338 | B2: Jago | C2: Świętokrzyskie | D2: Muszelki 3 | E2: 5 | F2: 4 | G2: 20 | J2: Sprzedawca
A3: 42132 | B3: Abis Mal | C3: Lubelskie | D3: Błazenek | E3: 19 | F3: 2.5 | G3: 47.5 | I3: Data | J3: Abis Mal | K3: Abu | L3: Alladyn | M3: Jago | N3: Jasmina | O3: Suma końcowa
A4: 42359 | B4: Alladyn | C4: Mazowieckie | D4: Błazenek | E4: 20 | F4: 2.5 | G4: 50 | I4: sty | J4: 1 | K4: 8 | L4: 1 | M4: 4 | N4: 7 | O4: 1
A5: 42340 | B5: Jasmina | C5: Mazowieckie | D5: Muszelki 1 | E5: 12 | F5: 2 | G5: 24 | I5: wrz | J5: 2 | K5: 7 | L5: 10 | M5: 12 | N5: 8 | O5: 12
A6: 42356 | B6: Jasmina | C6: Mazowieckie | D6: Żółwik | E6: 20 | F6: 5 | G6: 100 | I6: kwi | J6: 3 | K6: 11 | L6: 4 | M6: 10 | N6: 9 | O6: 11
A7: 42035 | B7: Jasmina | C7: Lubelskie | D7: Gąbki | E7: 16 | F7: 0.5 | G7: 8 | I7: paź | J7: 4 | K7: 1 | L7: 9 | M7: 7 | N7: 4 | O7: 3
A8: 42249 | B8: Abu | C8: Lubelskie | D8: Piasek | E8: 2 | F8: 0.1 | G8: 0.2 | I8: cze | J8: 5 | K8: 12 | L8: 3 | M8: 1 | N8: 11 | O8: 4
A9: 42022 | B9: Alladyn | C9: Świętokrzyskie | D9: Wodorosty | E9: 4 | F9: 0.2 | G9: 0.8 | I9: gru | J9: 6 | K9: 3 | L9: 7 | M9: 2 | N9: 6 | O9: 2
A10: 42031 | B10: Alladyn | C10: Wielkopolskie | D10: Piasek | E10: 4 | F10: 0.1 | G10: 0.4 | I10: lis | J10: 7 | K10: 10 | L10: 2 | M10: 6 | N10: 10 | O10: 7
A11: 42174 | B11: Abu | C11: Wielkopolskie | D11: Muszelki 3 | E11: 18 | F11: 4 | G11: 72 | I11: lut | J11: 8 | K11: 5 | L11: 11 | M11: 5 | N11: 1 | O11: 5
A12: 42050 | B12: Jasmina | C12: Wielkopolskie | D12: Muszelki 2 | E12: 15 | F12: 1.5 | G12: 22.5 | I12: lip | J12: 9 | K12: 4 | L12: 6 | M12: 3 | N12: 12 | O12: 8
A13: 42298 | B13: Alladyn | C13: Wielkopolskie | D13: Wodorosty | E13: 4 | F13: 0.2 | G13: 0.8 | I13: mar | J13: 10 | K13: 6 | L13: 8 | M13: 11 | N13: 3 | O13: 9
A14: 42360 | B14: Abu | C14: Lubelskie | D14: Muszelki 3 | E14: 6 | F14: 4 | G14: 24 | I14: maj | J14: 11 | K14: 2 | L14: 5 | M14: 9 | N14: 5 | O14: 6
A15: 42147 | B15: Abu | C15: Lubelskie | D15: Żółwik | E15: 6 | F15: 5 | G15: 30 | I15: sie | J15: 12 | K15: 9 | L15: 12 | M15: 8 | N15: 2 | O15: 10
A16: 42052 | B16: Abis Mal | C16: Mazowieckie | D16: Muszelki 1 | E16: 18 | F16: 2 | G16: 36 | I16: Suma końcowa
A17: 42071 | B17: Jasmina | C17: Świętokrzyskie | D17: Muszelki 3 | E17: 2 | F17: 4 | G17: 8
A18: 42087 | B18: Jasmina | C18: Lubelskie | D18: Piasek | E18: 11 | F18: 0.1 | G18: 1.1
A19: 42050 | B19: Jago | C19: Lubelskie | D19: Piasek | E19: 12 | F19: 0.1 | G19: 1.2
A20: 42264 | B20: Jasmina | C20: Lubelskie | D20: Żółwik | E20: 1 | F20: 5 | G20: 5
A21: 42202 | B21: Abis Mal | C21: Wielkopolskie | D21: Muszelki 2 | E21: 10 | F21: 1.5 | G21: 15
A22: 42049 | B22: Abu | C22: Wielkopolskie | D22: Żółwik | E22: 14 | F22: 5 | G22: 70
A23: 42096 | B23: Abis Mal | C23: Łódzkie | D23: Muszelki 3 | E23: 14 | F23: 4 | G23: 56
A24: 42010 | B24: Jago | C24: Świętokrzyskie | D24: Muszelki 3 | E24: 13 | F24: 4 | G24: 52
A25: 42066 | B25: Jago | C25: Mazowieckie | D25: Muszelki 1 | E25: 13 | F25: 2 | G25: 26
A26: 42240 | B26: Abis Mal | C26: Wielkopolskie | D26: Muszelki 1 | E26: 4 | F26: 2 | G26: 8
A27: 42249 | B27: Abis Mal | C27: Wielkopolskie | D27: Muszelki 1 | E27: 3 | F27: 2 | G27: 6
A28: 42249 | B28: Abu | C28: Łódzkie | D28: Błazenek | E28: 17 | F28: 2.5 | G28: 42.5
... A1001: 42261 | B1001: Abis Mal | C1001: Wielkopolskie | D1001: Wodorosty | E1001: 16 | F1001: 0.2 | G1001: 3.2

Sheet Wykres
A1: Data | B1: Sprzedawca | C1: Województwo | D1: Produkt | E1: Ilość | F1: Cena | G1: Wartość | I1: Województwo | J1: (Wszystko)
A2: 41510 | B2: Alladyn | C2: Wielkopolskie | D2: Żółwik | E2: 17 | F2: 5 | G2: =E2*F2 -> 85
A3: 41560 | B3: Jago | C3: Wielkopolskie | D3: Muszelki 3 | E3: 54 | F3: 4 | G3: =E3*F3 -> 216 | I3: Suma z Wartość | J3: Sprzedawca
A4: 41452 | B4: Abis Mal | C4: Łódzkie | D4: Wodorosty | E4: 81 | F4: 0.2 | G4: =E4*F4 -> 16.2 | I4: Produkt | J4: Abis Mal | K4: Abu | L4: Alladyn | M4: Jasmina
A5: 41455 | B5: Jasmina | C5: Mazowieckie | D5: Muszelki 3 | E5: 115 | F5: 4 | G5: =E5*F5 -> 460 | I5: Błazenek | J5: 1760 | K5: 1550 | L5: 1312.5 | M5: 1822.5
A6: 41456 | B6: Abis Mal | C6: Świętokrzyskie | D6: Muszelki 3 | E6: 133 | F6: 4 | G6: =E6*F6 -> 532 | I6: Muszelki 1 | J6: 916 | K6: 518 | L6: 576 | M6: 1694
A7: 41609 | B7: Jasmina | C7: Mazowieckie | D7: Błazenek | E7: 19 | F7: 2.5 | G7: =E7*F7 -> 47.5 | I7: Muszelki 2 | J7: 1467 | K7: 642 | L7: 769.5 | M7: 1089
A8: 41427 | B8: Jago | C8: Łódzkie | D8: Żółwik | E8: 45 | F8: 5 | G8: =E8*F8 -> 225 | I8: Muszelki 3 | J8: 2724 | K8: 1444 | L8: 4148 | M8: 3136
A9: 41496 | B9: Jago | C9: Mazowieckie | D9: Muszelki 2 | E9: 100 | F9: 1.5 | G9: =E9*F9 -> 150 | I9: Żółwik | J9: 275 | K9: 1885 | L9: 2580 | M9: 3280
A10: 41507 | B10: Abis Mal | C10: Świętokrzyskie | D10: Gąbki | E10: 37 | F10: 0.5 | G10: =E10*F10 -> 18.5
A11: 41592 | B11: Alladyn | C11: Świętokrzyskie | D11: Piasek | E11: 85 | F11: 0.1 | G11: =E11*F11 -> 8.5
A12: 41498 | B12: Abis Mal | C12: Lubelskie | D12: Żółwik | E12: 30 | F12: 5 | G12: =E12*F12 -> 150
A13: 41582 | B13: Jasmina | C13: Mazowieckie | D13: Piasek | E13: 118 | F13: 0.1 | G13: =E13*F13 -> 11.8
A14: 41505 | B14: Abis Mal | C14: Lubelskie | D14: Muszelki 2 | E14: 108 | F14: 1.5 | G14: =E14*F14 -> 162
A15: 41629 | B15: Alladyn | C15: Wielkopolskie | D15: Muszelki 2 | E15: 18 | F15: 1.5 | G15: =E15*F15 -> 27
A16: 41439 | B16: Jasmina | C16: Wielkopolskie | D16: Muszelki 1 | E16: 84 | F16: 2 | G16: =E16*F16 -> 168
A17: 41443 | B17: Jasmina | C17: Wielkopolskie | D17: Żółwik | E17: 64 | F17: 5 | G17: =E17*F17 -> 320
A18: 41572 | B18: Abis Mal | C18: Świętokrzyskie | D18: Muszelki 1 | E18: 29 | F18: 2 | G18: =E18*F18 -> 58
A19: 41544 | B19: Jago | C19: Łódzkie | D19: Muszelki 2 | E19: 26 | F19: 1.5 | G19: =E19*F19 -> 39
A20: 41563 | B20: Jasmina | C20: Mazowieckie | D20: Muszelki 2 | E20: 148 | F20: 1.5 | G20: =E20*F20 -> 222
A21: 41595 | B21: Abis Mal | C21: Świętokrzyskie | D21: Wodorosty | E21: 13 | F21: 0.2 | G21: =E21*F21 -> 2.6
... A325: 41554 | B325: Alladyn | C325: Łódzkie | D325: Błazenek | E325: 106 | F325: 2.5 | G325: =E325*F325 -> 265

Sheet Dolnośląskie
A1: Województwo | B1: Dolnośląskie
A3: Suma z Sprzedaż | B3: Etykiety kolumn
A4: Etykiety wierszy | B4: Burza | C4: Chmura | D4: Deszcz | E4: Grad | F4: Grom | G4: Słońce | H4: Tęcza | I4: Suma końcowa
A5: Alex | B5: 137.7 | C5: 1962.95 | D5: 1198.25 | F5: 1834.9 | H5: 502.85 | I5: 5636.65
A6: Atylla | B6: 704.25 | C6: 4141.7 | D6: 1604.05 | E6: 1894.5 | F6: 1799.3 | I6: 10143.8
A7: Dory | B7: 863.1 | C7: 1603.05 | F7: 1264.4 | H7: 1972.3 | I7: 5702.85
A8: Dr Ladazzo | B8: 1975 | C8: 6892.45 | D8: 2358.2 | F8: 1624.2 | G8: 734.45 | H8: 3192.8 | I8: 16777.1
A9: Gloria | B9: 277.6 | C9: 582.1 | H9: 2172.95 | I9: 3032.65
A10: Idol | C10: 1180 | D10: 573.75 | E10: 1061 | G10: 1188.85 | H10: 2613.6 | I10: 6617.2
A11: Julian | C11: 926.55 | D11: 1217.65 | E11: 680.65 | I11: 2824.85
A12: Marlena | C12: 1689.5 | E12: 151.5 | F12: 2227.4 | G12: 1431.85 | I12: 5500.25
A13: Marlin | B13: 1049.15 | F13: 479.35 | G13: 1670.1 | H13: 2164.05 | I13: 5362.65
A14: Marty | C14: 1938.35 | D14: 2264.6 | H14: 1697.5 | I14: 5900.45
A15: Maurice | D15: 2039.6 | G15: 1473.4 | H15: 2083.1 | I15: 5596.1
A16: Melman | C16: 1262.65 | D16: 652.3 | E16: 3300.85 | F16: 1290.7 | G16: 1586 | H16: 3067.5 | I16: 11160
A17: Mindy | E17: 2506.75 | G17: 3394.4 | H17: 1860.05 | I17: 7761.2
A18: Nemo | B18: 2489.95 | D18: 137.15 | E18: 2256.1 | G18: 1194.65 | I18: 6077.85
A19: Penny | B19: 2084.05 | C19: 3379.55 | D19: 1556.7 | I19: 7020.3
A20: Piorun | B20: 816 | C20: 742 | I20: 1558
A21: Skipper | B21: 1674.6 | C21: 2208.3 | E21: 1445.6 | F21: 774.9 | G21: 907.9 | H21: 1928.9 | I21: 8940.2
A22: Suma końcowa | B22: 12071.4 | C22: 28509.15 | D22: 13602.25 | E22: 13296.95 | F22: 11295.15 | G22: 13581.6 | H22: 23255.6 | I22: 115612.1

Sheet Kujawsko-pomorskie
A1: Województwo | B1: Kujawsko-pomorskie
A3: Suma z Sprzedaż | B3: Etykiety kolumn
A4: Etykiety wierszy | B4: Burza | C4: Chmura | D4: Deszcz | E4: Grad | F4: Grom | G4: Słońce | H4: Tęcza | I4: Suma końcowa
A5: Alex | B5: 2431.15 | C5: 724.05 | E5: 1756.8 | H5: 628.65 | I5: 5540.65
A6: Atylla | C6: 1623.65 | D6: 2121.75 | F6: 1802.7 | I6: 5548.1
A7: Dory | C7: 1359.3 | E7: 3166.1 | F7: 106.3 | G7: 2715.35 | I7: 7347.05
A8: Dr Ladazzo | C8: 1945 | D8: 3441.15 | E8: 863.15 | F8: 1481.65 | I8: 7730.95
A9: Gloria | B9: 3592.85 | C9: 485.25 | D9: 310 | F9: 2739.8 | G9: 495.65 | H9: 1859.35 | I9: 9482.9
A10: Idol | B10: 594.6 | D10: 797.4 | E10: 2951.85 | F10: 1461.75 | H10: 2081.8 | I10: 7887.4
A11: Julian | B11: 715.4 | C11: 592.85 | F11: 4676.4 | G11: 1230.7 | H11: 118.95 | I11: 7334.3
A12: Marlena | D12: 1469.45 | E12: 120.75 | G12: 1325.8 | H12: 1397.95 | I12: 4313.95
A13: Marlin | B13: 679.55 | C13: 1707.9 | E13: 1362.15 | I13: 3749.6
A14: Marty | D14: 1061.85 | F14: 245.95 | G14: 1113.75 | I14: 2421.55
A15: Maurice | B15: 443.2 | C15: 1731.5 | D15: 578.2 | E15: 1636.6 | F15: 105.15 | G15: 1631.55 | H15: 1822.6 | I15: 7948.8
A16: Melman | B16: 704.75 | D16: 2021.85 | G16: 1784.35 | H16: 3327.55 | I16: 7838.5
A17: Mindy | B17: 2073.55 | D17: 826.8 | E17: 201.75 | F17: 386.4 | G17: 1940.85 | I17: 5429.35
A18: Nemo | E18: 194 | G18: 1965.5 | H18: 537.95 | I18: 2697.45
A19: Penny | B19: 3572.25 | C19: 1641 | H19: 2641 | I19: 7854.25
A20: Piorun | E20: 1346.35 | F20: 1039 | G20: 3558.95 | I20: 5944.3
A21: Skipper | B21: 1353.2 | C21: 573 | D21: 3536.35 | E21: 1346.45 | F21: 1779.15 | G21: 1235.1 | H21: 1990.15 | I21: 11813.4
A22: Suma końcowa | B22: 16160.5 | C22: 12383.5 | D22: 16164.8 | E22: 14945.95 | F22: 15824.25 | G22: 18997.55 | H22: 16405.95 | I22: 110882.5

Sheet Lubelskie
A1: Województwo | B1: Lubelskie
A3: Suma z Sprzedaż | B3: Etykiety kolumn
A4: Etykiety wierszy | B4: Burza | C4: Chmura | D4: Deszcz | E4: Grad | F4: Grom | G4: Słońce | H4: Tęcza | I4: Suma końcowa
A5: Alex | B5: 485.3 | I5: 485.3
A6: Atylla | B6: 766.4 | E6: 1606.05 | G6: 1844.3 | I6: 4216.75
A7: Dory | B7: 1856.95 | C7: 1994.2 | D7: 1754.2 | F7: 3442.85 | H7: 2060.3 | I7: 11108.5
A8: Dr Ladazzo | B8: 449.35 | C8: 299.6 | D8: 1082.95 | E8: 2002.75 | F8: 723.35 | H8: 2591 | I8: 7149
A9: Gloria | E9: 1583.8 | G9: 225.4 | I9: 1809.2
A10: Idol | C10: 815.35 | D10: 1955.6 | E10: 1010.45 | F10: 3140.95 | G10: 2116.45 | I10: 9038.8
A11: Julian | B11: 1571.25 | C11: 1926.8 | D11: 4070.9 | G11: 3594.1 | H11: 1302.25 | I11: 12465.3
A12: Marlena | C12: 1805.9 | D12: 1058.8 | E12: 430.15 | F12: 856.3 | H12: 3546 | I12: 7697.15
A13: Marlin | B13: 890.05 | D13: 641.15 | G13: 2278.9 | I13: 3810.1
A14: Marty | D14: 289.9 | E14: 3015.45 | G14: 2752.65 | I14: 6058
A15: Maurice | B15: 3351.8 | D15: 1125 | E15: 1045.3 | F15: 3431.55 | G15: 1368.6 | I15: 10322.25
A16: Melman | C16: 2573.7 | D16: 1574.4 | E16: 1247.95 | F16: 240.25 | G16: 754.85 | I16: 6391.15
A17: Mindy | B17: 1121.75 | C17: 1802.15 | D17: 1238.65 | E17: 2149.5 | F17: 1524.35 | G17: 822.4 | I17: 8658.8
A18: Nemo | C18: 329.65 | D18: 3549.25 | E18: 1821.9 | G18: 1556.35 | H18: 2533.25 | I18: 9790.4
A19: Penny | B19: 1425.5 | C19: 371.9 | G19: 3119.8 | I19: 4917.2
A20: Piorun | B20: 1370.1 | C20: 2242.25 | D20: 420.85 | E20: 798 | F20: 953.15 | G20: 1718.8 | I20: 7503.15
A21: Skipper | C21: 2597.2 | D21: 1328.15 | F21: 1374.6 | G21: 1780.4 | H21: 301.55 | I21: 7381.9
A22: Suma końcowa | B22: 13288.45 | C22: 16758.7 | D22: 20089.8 | E22: 16711.3 | F22: 15687.35 | G22: 23933 | H22: 12334.35 | I22: 118802.95

Sheet Lubuskie
A1: Województwo | B1: Lubuskie
A3: Suma z Sprzedaż | B3: Etykiety kolumn
A4: Etykiety wierszy | B4: Burza | C4: Chmura | D4: Deszcz | E4: Grad | F4: Grom | G4: Słońce | H4: Tęcza | I4: Suma końcowa
A5: Alex | E5: 3253.35 | F5: 2308.9 | G5: 1287.1 | I5: 6849.35
A6: Atylla | B6: 1028.8 | C6: 396.85 | D6: 1060.05 | F6: 2820 | G6: 1063.4 | H6: 1807.45 | I6: 8176.55
A7: Dory | F7: 1858.6 | G7: 797.3 | I7: 2655.9
A8: Dr Ladazzo | B8: 2018.1 | C8: 777.85 | D8: 1929.85 | E8: 1325.25 | F8: 2225.05 | I8: 8276.1
A9: Gloria | B9: 3231.15 | C9: 298.5 | D9: 1843.3 | E9: 1677.15 | G9: 2531.25 | H9: 1951.7 | I9: 11533.05
A10: Idol | B10: 1823.95 | C10: 649.8 | I10: 2473.75
A11: Julian | B11: 447.75 | D11: 702.3 | I11: 1150.05
A12: Marlena | B12: 156.5 | D12: 911.45 | G12: 1166.45 | H12: 251.55 | I12: 2485.95
A13: Marlin | B13: 1478.15 | C13: 1555.75 | D13: 1494 | E13: 190.75 | F13: 160.95 | G13: 3347.45 | H13: 1387.6 | I13: 9614.65
A14: Marty | B14: 1366.4 | C14: 1878.8 | E14: 693.9 | I14: 3939.1
A15: Maurice | C15: 2343.95 | D15: 2524.9 | E15: 847.05 | F15: 1589.35 | H15: 778.7 | I15: 8083.95
A16: Melman | B16: 3221.85 | D16: 1870.1 | F16: 1369.9 | G16: 1178.95 | H16: 980.8 | I16: 8621.6
A17: Mindy | C17: 1554.3 | E17: 653.25 | F17: 2060.55 | G17: 1783.75 | H17: 1753.8 | I17: 7805.65
A18: Nemo | C18: 1455.1 | D18: 1922.95 | G18: 3464.35 | I18: 6842.4
A19: Penny | C19: 1269.6 | D19: 971.5 | F19: 2433.9 | G19: 506.1 | I19: 5181.1
A20: Piorun | B20: 1962.6 | C20: 2804.55 | D20: 1504.5 | E20: 4142.8 | G20: 5541.55 | H20: 1768.65 | I20: 17724.65
A21: Skipper | B21: 1113.9 | H21: 1809.2 | I21: 2923.1
A22: Suma końcowa | B22: 17849.15 | C22: 14985.05 | D22: 16734.9 | E22: 12783.5 | F22: 16827.2 | G22: 22667.65 | H22: 12489.45 | I22: 114336.9

Sheet Łódzkie
A1: Województwo | B1: Łódzkie
A3: Suma z Sprzedaż | B3: Etykiety kolumn
A4: Etykiety wierszy | B4: Burza | C4: Chmura | D4: Deszcz | E4: Grad | F4: Grom | G4: Słońce | H4: Tęcza | I4: Suma końcowa
A5: Alex | B5: 2147 | E5: 1057.55 | F5: 849.95 | G5: 697.15 | H5: 2355.85 | I5: 7107.5
A6: Atylla | D6: 321.6 | F6: 1656.1 | G6: 609.6 | I6: 2587.3
A7: Dory | B7: 517.25 | C7: 2761.9 | D7: 2677.2 | F7: 2594.35 | H7: 1783.1 | I7: 10333.8
A8: Dr Ladazzo | B8: 2334.05 | C8: 749.7 | D8: 3042.7 | E8: 1745.85 | F8: 2585.35 | G8: 1169.9 | H8: 3175.65 | I8: 14803.2
A9: Gloria | C9: 1614.75 | E9: 884.85 | H9: 416.45 | I9: 2916.05
A10: Idol | E10: 1151.2 | F10: 3241.5 | G10: 1401.35 | I10: 5794.05
A11: Julian | B11: 623.15 | D11: 3550.45 | F11: 580.95 | G11: 2827.2 | H11: 989.8 | I11: 8571.55
A12: Marlena | C12: 2336.6 | F12: 3518.35 | H12: 1056 | I12: 6910.95
A13: Marlin | B13: 815.65 | C13: 867.45 | D13: 3820.9 | E13: 1236.5 | G13: 1725.65 | H13: 835.9 | I13: 9302.05
A14: Marty | B14: 469.55 | C14: 1840.8 | D14: 161.35 | E14: 120.05 | G14: 2019.6 | I14: 4611.35
A15: Maurice | B15: 5516.95 | D15: 1141.9 | E15: 3104.45 | F15: 115.85 | G15: 1258.45 | H15: 978.45 | I15: 12116.05
A16: Melman | B16: 5030.05 | C16: 254.85 | D16: 1993.65 | F16: 2510.9 | I16: 9789.45
A17: Mindy | B17: 1768.55 | C17: 1721.85 | E17: 4037.3 | G17: 1702.45 | I17: 9230.15
A18: Nemo | C18: 967.65 | D18: 438.95 | E18: 1538.9 | G18: 1982.45 | I18: 4927.95
A19: Penny | B19: 1787.7 | C19: 2193.15 | E19: 1519.7 | G19: 1056.05 | H19: 299.4 | I19: 6856
A20: Piorun | C20: 1336.5 | D20: 178.5 | I20: 1515
A21: Skipper | B21: 1263.6 | D21: 596.65 | I21: 1860.25
A22: Suma końcowa | B22: 22273.5 | C22: 16645.2 | D22: 17923.85 | E22: 16396.35 | F22: 17653.3 | G22: 16449.85 | H22: 11890.6 | I22: 119232.65

Sheet Małopolskie (2)
A1: Województwo | B1: Małopolskie
A3: Suma z Sprzedaż | B3: Etykiety kolumn
A4: Etykiety wierszy | B4: Burza | C4: Chmura | D4: Deszcz | E4: Grad | F4: Grom | G4: Słońce | H4: Tęcza | I4: Suma końcowa
A5: Alex | B5: 1552.75 | C5: 499.85 | E5: 4609.3 | H5: 2469.4 | I5: 9131.3
A6: Atylla | C6: 2269.1 | D6: 1062 | F6: 1617.45 | I6: 4948.55
A7: Dory | B7: 190.4 | C7: 949.15 | H7: 1842.8 | I7: 2982.35
A8: Dr Ladazzo | B8: 2337.6 | C8: 1340.9 | D8: 2514.1 | F8: 1821.5 | G8: 585.5 | H8: 2970.9 | I8: 11570.5
A9: Gloria | B9: 1784.6 | C9: 1733.2 | E9: 1673 | F9: 1121.3 | G9: 915.95 | H9: 1137.8 | I9: 8365.85
A10: Idol | B10: 1111.25 | D10: 749.45 | F10: 1404.75 | G10: 3793.65 | H10: 493.4 | I10: 7552.5
A11: Julian | B11: 2403.15 | C11: 2512 | E11: 1310.35 | F11: 1036.35 | G11: 1185.85 | H11: 965.1 | I11: 9412.8
A12: Marlena | B12: 2042.65 | C12: 684.5 | E12: 368.35 | F12: 1027.45 | G12: 1803.6 | H12: 494.5 | I12: 6421.05
A13: Marlin | B13: 510.35 | C13: 1471.65 | E13: 709.9 | G13: 1939.05 | I13: 4630.95
A14: Marty | B14: 111.45 | D14: 1497.55 | E14: 1079.1 | F14: 3795.95 | I14: 6484.05
A15: Maurice | C15: 1675.65 | E15: 1384.95 | G15: 774.75 | I15: 3835.35
A16: Melman | B16: 530.55 | C16: 1514.85 | D16: 1459.6 | F16: 2302.1 | H16: 3058.8 | I16: 8865.9
A17: Mindy | B17: 1849.45 | D17: 219.6 | E17: 2772.45 | F17: 429.5 | H17: 272.05 | I17: 5543.05
A18: Nemo | G18: 947.65 | I18: 947.65
A19: Penny | C19: 412 | D19: 101.05 | H19: 1201.45 | I19: 1714.5
A20: Piorun | C20: 307.05 | E20: 461.7 | F20: 1955.55 | H20: 859.1 | I20: 3583.4
A21: Skipper | E21: 235 | F21: 1862.25 | G21: 1343.45 | H21: 468.75 | I21: 3909.45
A22: Suma końcowa | B22: 14424.2 | C22: 15369.9 | D22: 7603.35 | E22: 14604.1 | F22: 18374.15 | G22: 13289.45 | H22: 16234.05 | I22: 99899.2

Sheet Mazowieckie (2)
A1: Województwo | B1: Mazowieckie
A3: Suma z Sprzedaż | B3: Etykiety kolumn
A4: Etykiety wierszy | B4: Burza | C4: Chmura | D4: Deszcz | E4: Grad | F4: Grom | G4: Słońce | H4: Tęcza | I4: Suma końcowa
A5: Alex | B5: 675.05 | C5: 1331.85 | F5: 1604.3 | G5: 541.85 | H5: 1602.25 | I5: 5755.3
A6: Atylla | C6: 1003.5 | D6: 276.4 | F6: 2488.7 | H6: 765.45 | I6: 4534.05
A7: Dory | B7: 1594.15 | F7: 1166.85 | G7: 946.25 | H7: 4162.75 | I7: 7870
A8: Dr Ladazzo | B8: 1933.65 | D8: 2608.85 | E8: 1507.95 | G8: 858.1 | H8: 1890.9 | I8: 8799.45
A9: Gloria | C9: 1275.85 | E9: 1368 | G9: 1413.95 | H9: 152 | I9: 4209.8
A10: Idol | B10: 1566.25 | D10: 452.35 | E10: 1595.1 | F10: 2583.75 | I10: 6197.45
A11: Julian | B11: 353.6 | E11: 1503.95 | G11: 1124 | H11: 2010.6 | I11: 4992.15
A12: Marlena | B12: 683.85 | C12: 3689.75 | D12: 1067.9 | E12: 1178.55 | F12: 1765.55 | H12: 2405.75 | I12: 10791.35
A13: Marlin | C13: 1340.7 | E13: 4068.75 | F13: 1961.35 | G13: 1238.2 | I13: 8609
A14: Marty | B14: 1941.45 | C14: 2873 | E14: 2055 | G14: 1061.8 | H14: 977.7 | I14: 8908.95
A15: Maurice | B15: 125.5 | D15: 3971.85 | F15: 3216.85 | H15: 966.85 | I15: 8281.05
A16: Melman | D16: 416.3 | E16: 2612.65 | F16: 4791.2 | G16: 942.35 | H16: 3007.9 | I16: 11770.4
A17: Mindy | B17: 398 | C17: 1645.75 | D17: 100.65 | E17: 635.3 | G17: 1126.5 | H17: 1398.9 | I17: 5305.1
A18: Nemo | B18: 1432.5 | C18: 2678.05 | D18: 773.2 | E18: 3037.8 | F18: 1627 | G18: 474.45 | I18: 10023
A19: Penny | B19: 3260 | G19: 448.95 | H19: 1955.85 | I19: 5664.8
A20: Piorun | B20: 585 | C20: 2389.65 | I20: 2974.65
A21: Skipper | D21: 1500.05 | E21: 1993.55 | H21: 3735.35 | I21: 7228.95
A22: Suma końcowa | B22: 14549 | C22: 18228.1 | D22: 11167.55 | E22: 21556.6 | F22: 21205.55 | G22: 10176.4 | H22: 25032.25 | I22: 121915.45

Sheet Opolskie
A1: Województwo | B1: Opolskie
A3: Suma z Sprzedaż | B3: Etykiety kolumn
A4: Etykiety wierszy | B4: Burza | C4: Chmura | D4: Deszcz | E4: Grad | F4: Grom | G4: Słońce | H4: Tęcza | I4: Suma końcowa
A5: Alex | B5: 1027 | E5: 3431.3 | G5: 1117.8 | H5: 1148.5 | I5: 6724.6
A6: Atylla | B6: 1562.95 | C6: 1655.8 | H6: 943.8 | I6: 4162.55
A7: Dory | B7: 1011.3 | D7: 2520.2 | E7: 800 | F7: 1348.05 | H7: 752.05 | I7: 6431.6
A8: Dr Ladazzo | C8: 398 | E8: 1843.8 | F8: 3572.2 | G8: 3668.6 | H8: 1401.2 | I8: 10883.8
A9: Gloria | C9: 3830.4 | E9: 1324.6 | F9: 881.85 | G9: 597.45 | H9: 4124.85 | I9: 10759.15
A10: Idol | B10: 1297.75 | D10: 1641.1 | E10: 1463.45 | G10: 1309.95 | H10: 2998.4 | I10: 8710.65
A11: Julian | C11: 2225.5 | E11: 3834.05 | F11: 181.1 | G11: 924.95 | I11: 7165.6
A12: Marlena | B12: 1383.95 | C12: 843 | I12: 2226.95
A13: Marlin | B13: 3623.95 | C13: 594.2 | D13: 1352.35 | E13: 1037.95 | G13: 1725.4 | H13: 1053 | I13: 9386.85
A14: Marty | C14: 877.55 | E14: 477.05 | G14: 1537.25 | H14: 823.7 | I14: 3715.55
A15: Maurice | B15: 398.3 | C15: 2626.5 | D15: 3489.45 | E15: 665.6 | F15: 4552.5 | H15: 1535.75 | I15: 13268.1
A16: Melman | C16: 1597.5 | D16: 3892.8 | G16: 157.2 | H16: 2351.55 | I16: 7999.05
A17: Mindy | B17: 678 | C17: 211.85 | D17: 1594.9 | E17: 194.6 | F17: 227.8 | H17: 182.15 | I17: 3089.3
A18: Nemo | D18: 121.05 | E18: 3380.8 | H18: 1127.85 | I18: 4629.7
A19: Penny | D19: 625.65 | F19: 298.95 | G19: 909.7 | H19: 961.8 | I19: 2796.1
A20: Piorun | C20: 389.6 | E20: 1656.5 | F20: 1976.5 | G20: 1911 | I20: 5933.6
A21: Skipper | B21: 1604.5 | C21: 1979.5 | D21: 1072.05 | E21: 1654.75 | G21: 1072.15 | H21: 887.8 | I21: 8270.75
A22: Suma końcowa | B22: 12587.7 | C22: 17229.4 | D22: 16309.55 | E22: 21764.45 | F22: 13038.95 | G22: 14931.45 | H22: 20292.4 | I22: 116153.9

Sheet Podkarpackie
A1: Województwo | B1: Podkarpackie
A3: Suma z Sprzedaż | B3: Etykiety kolumn
A4: Etykiety wierszy | B4: Burza | C4: Chmura | D4: Deszcz | E4: Grad | F4: Grom | G4: Słońce | H4: Tęcza | I4: Suma końcowa
A5: Alex | B5: 2755 | C5: 460.85 | D5: 3880.1 | E5: 1816.4 | F5: 130.6 | G5: 1681.55 | H5: 2485.05 | I5: 13209.55
A6: Atylla | B6: 1164.9 | D6: 1063.35 | G6: 272 | H6: 961.5 | I6: 3461.75
A7: Dory | B7: 1915.55 | C7: 2027.8 | F7: 1747.4 | G7: 1108 | I7: 6798.75
A8: Dr Ladazzo | D8: 567.2 | G8: 1548 | H8: 171.3 | I8: 2286.5
A9: Gloria | B9: 951.15 | C9: 1290.85 | D9: 2158.8 | E9: 1686.1 | F9: 5269.3 | H9: 664.45 | I9: 12020.65
A10: Idol | B10: 4419.65 | D10: 810.05 | E10: 774.85 | F10: 1290.05 | I10: 7294.6
A11: Julian | C11: 446.7 | D11: 552.5 | E11: 337.45 | H11: 1867.2 | I11: 3203.85
A12: Marlena | B12: 2888.65 | F12: 2496.75 | G12: 1804.65 | H12: 421.7 | I12: 7611.75
A13: Marlin | B13: 1620.65 | C13: 2151.25 | D13: 310.45 | F13: 1600.05 | G13: 1908.3 | H13: 1089.05 | I13: 8679.75
A14: Marty | B14: 1484.9 | C14: 1617.65 | E14: 2610.65 | I14: 5713.2
A15: Maurice | D15: 3112.4 | E15: 1026.25 | F15: 1796.7 | I15: 5935.35
A16: Melman | B16: 3789.45 | C16: 3143.75 | D16: 3035.8 | F16: 1790.65 | I16: 11759.65
A17: Mindy | B17: 1229.45 | C17: 3227.3 | D17: 414.7 | F17: 896.8 | G17: 103.55 | H17: 681.3 | I17: 6553.1
A18: Nemo | D18: 897.75 | F18: 1820.1 | G18: 1323.65 | H18: 791.45 | I18: 4832.95
A19: Penny | B19: 301.35 | E19: 518.2 | G19: 2711.8 | H19: 1723.6 | I19: 5254.95
A20: Piorun | D20: 203.9 | E20: 1616.05 | G20: 920.4 | H20: 1389.25 | I20: 4129.6
A21: Skipper | C21: 2894.55 | E21: 2211.05 | F21: 249.2 | H21: 770.3 | I21: 6125.1
A22: Suma końcowa | B22: 22520.7 | C22: 17260.7 | D22: 17007 | E22: 12597 | F22: 19087.6 | G22: 13381.9 | H22: 13016.15 | I22: 114871.05

Sheet Podlaskie
A1: Województwo | B1: Podlaskie
A3: Suma z Sprzedaż | B3: Etykiety kolumn
A4: Etykiety wierszy | B4: Burza | C4: Chmura | D4: Deszcz | E4: Grad | F4: Grom | G4: Słońce | H4: Tęcza | I4: Suma końcowa
A5: Alex | E5: 4178.45 | F5: 717.9 | G5: 1572.8 | I5: 6469.15
A6: Atylla | B6: 2578.4 | D6: 4439.9 | E6: 1893.65 | F6: 1129.7 | H6: 936.15 | I6: 10977.8
A7: Dory | C7: 1535.7 | D7: 1123 | F7: 1581.8 | H7: 1955.65 | I7: 6196.15
A8: Dr Ladazzo | B8: 1994.55 | D8: 796.65 | G8: 2119.05 | H8: 1744.4 | I8: 6654.65
A9: Gloria | E9: 761.55 | G9: 963.95 | I9: 1725.5
A10: Idol | B10: 520.75 | C10: 2528.9 | D10: 912.25 | E10: 770.6 | I10: 4732.5
A11: Julian | B11: 315.85 | C11: 2887.9 | F11: 274.6 | H11: 412.45 | I11: 3890.8
A12: Marlena | C12: 276.2 | F12: 646.8 | I12: 923
A13: Marlin | B13: 1966.95 | D13: 2226.9 | E13: 2987.3 | H13: 754.5 | I13: 7935.65
A14: Marty | B14: 2479.9 | C14: 1029.6 | E14: 1599.1 | H14: 533.75 | I14: 5642.35
A15: Maurice | B15: 257.15 | D15: 3147.85 | E15: 1147.55 | F15: 874.35 | G15: 118.25 | I15: 5545.15
A16: Melman | C16: 479.55 | D16: 1627.15 | H16: 928.65 | I16: 3035.35
A17: Mindy | E17: 1893 | F17: 1861.85 | G17: 1132.25 | H17: 1730.85 | I17: 6617.95
A18: Nemo | D18: 1820.4 | E18: 5728.95 | F18: 1250.85 | H18: 1345.35 | I18: 10145.55
A19: Penny | B19: 1165.25 | C19: 2145.8 | D19: 604.9 | E19: 1092.2 | F19: 713.85 | G19: 2756.35 | H19: 1056.2 | I19: 9534.55
A20: Piorun | D20: 563.5 | E20: 1266.45 | G20: 2340.55 | I20: 4170.5
